exception in epoch1
Traceback (most recent call last):
  File "C:\Users\83549\Github Projects\Radiogenemics--on-Ivy-Gap-Branch\train.py", line 126, in <module>
    average_loss_list, loss_list.sum() / len(loss_list))
  File "C:\Users\83549\anaconda3\envs\PyTorch-gpu\lib\site-packages\numpy\core\_methods.py", line 48, in _sum
    return umr_sum(a, axis, dtype, out, keepdims, initial, where)
TypeError: unsupported operand type(s) for +: 'builtin_function_or_method' and 'builtin_function_or_method'

exception in epoch1
Traceback (most recent call last):
  File "C:\Users\83549\Github Projects\Radiogenemics--on-Ivy-Gap-Branch\train.py", line 132, in <module>
    predict_image = net(image)
  File "C:\Users\83549\anaconda3\envs\PyTorch-gpu\lib\site-packages\torch\nn\modules\module.py", line 1051, in _call_impl
    return forward_call(*input, **kwargs)
  File "C:\Users\83549\Github Projects\Radiogenemics--on-Ivy-Gap-Branch\unet.py", line 83, in forward
    R1 = self.c9(self.u4(R2, L1))
  File "C:\Users\83549\anaconda3\envs\PyTorch-gpu\lib\site-packages\torch\nn\modules\module.py", line 1051, in _call_impl
    return forward_call(*input, **kwargs)
  File "C:\Users\83549\Github Projects\Radiogenemics--on-Ivy-Gap-Branch\unet.py", line 23, in forward
    return self.layer(x)
  File "C:\Users\83549\anaconda3\envs\PyTorch-gpu\lib\site-packages\torch\nn\modules\module.py", line 1051, in _call_impl
    return forward_call(*input, **kwargs)
  File "C:\Users\83549\anaconda3\envs\PyTorch-gpu\lib\site-packages\torch\nn\modules\container.py", line 139, in forward
    input = module(input)
  File "C:\Users\83549\anaconda3\envs\PyTorch-gpu\lib\site-packages\torch\nn\modules\module.py", line 1051, in _call_impl
    return forward_call(*input, **kwargs)
  File "C:\Users\83549\anaconda3\envs\PyTorch-gpu\lib\site-packages\torch\nn\modules\conv.py", line 443, in forward
    return self._conv_forward(input, self.weight, self.bias)
  File "C:\Users\83549\anaconda3\envs\PyTorch-gpu\lib\site-packages\torch\nn\modules\conv.py", line 436, in _conv_forward
    return F.conv2d(F.pad(input, self._reversed_padding_repeated_twice, mode=self.padding_mode),
RuntimeError: CUDA out of memory. Tried to allocate 64.00 MiB (GPU 0; 6.00 GiB total capacity; 5.27 GiB already allocated; 0 bytes free; 5.31 GiB reserved in total by PyTorch)

exception in epoch1
Traceback (most recent call last):
  File "C:\Users\83549\Github Projects\Radiogenemics--on-Ivy-Gap-Branch\train.py", line 183, in <module>
    evl_dict = trainHelper.evalation_all(train_path=[os.path.join(train_path, 'Preds'), os.path.join(train_path, 'Masks')], validation_path=[os.path.join(validation_path, 'Preds'), os.path.join(validation_path, 'Masks')], test_path=[os.path.join(test_path, 'Preds'), os.path.join(test_path, 'Masks')], ROC_cruve_save_path=ROC_path)
  File "C:\Users\83549\Github Projects\Radiogenemics--on-Ivy-Gap-Branch\trainHelper.py", line 170, in evalation_all
    thresold = ROC_to_calculate_thresold(pred_path=train_path[0], truth_path=train_path[1], save_path=ROC_cruve_save_path, save_or_not=True)
  File "C:\Users\83549\Github Projects\Radiogenemics--on-Ivy-Gap-Branch\trainHelper.py", line 78, in ROC_to_calculate_thresold
    for i in len(preds):
TypeError: 'int' object is not iterable

exception in epoch1
Traceback (most recent call last):
  File "C:\Users\83549\Github Projects\Radiogenemics--on-Ivy-Gap-Branch\train.py", line 183, in <module>
    evl_dict = trainHelper.evalation_all(train_path=[os.path.join(train_path, 'Preds'), os.path.join(train_path, 'Masks')], validation_path=[os.path.join(validation_path, 'Preds'), os.path.join(validation_path, 'Masks')], test_path=[os.path.join(test_path, 'Preds'), os.path.join(test_path, 'Masks')], ROC_cruve_save_path=ROC_path)
  File "C:\Users\83549\Github Projects\Radiogenemics--on-Ivy-Gap-Branch\trainHelper.py", line 170, in evalation_all
    thresold = ROC_to_calculate_thresold(pred_path=train_path[0], truth_path=train_path[1], save_path=ROC_cruve_save_path, save_or_not=True)
  File "C:\Users\83549\Github Projects\Radiogenemics--on-Ivy-Gap-Branch\trainHelper.py", line 79, in ROC_to_calculate_thresold
    FP, FN, TP, TN = 0
TypeError: cannot unpack non-iterable int object

exception in epoch1
Traceback (most recent call last):
  File "C:\Users\83549\Github Projects\Radiogenemics--on-Ivy-Gap-Branch\train.py", line 183, in <module>
    evl_dict = trainHelper.evalation_all(train_path=[os.path.join(train_path, 'Preds'), os.path.join(train_path, 'Masks')], validation_path=[os.path.join(validation_path, 'Preds'), os.path.join(validation_path, 'Masks')], test_path=[os.path.join(test_path, 'Preds'), os.path.join(test_path, 'Masks')], ROC_cruve_save_path=ROC_path)
  File "C:\Users\83549\Github Projects\Radiogenemics--on-Ivy-Gap-Branch\trainHelper.py", line 171, in evalation_all
    thresold = ROC_to_calculate_thresold(pred_path=train_path[0], truth_path=train_path[1], save_path=ROC_cruve_save_path, save_or_not=True)
  File "C:\Users\83549\Github Projects\Radiogenemics--on-Ivy-Gap-Branch\trainHelper.py", line 79, in ROC_to_calculate_thresold
    FP, FN, TP, TN = 0
TypeError: cannot unpack non-iterable int object

exception in epoch1
Traceback (most recent call last):
  File "C:\Users\83549\Github Projects\Radiogenemics--on-Ivy-Gap-Branch\train.py", line 183, in <module>
    evl_dict = trainHelper.evalation_all(train_path=[os.path.join(train_path, 'Preds'), os.path.join(train_path, 'Masks')], validation_path=[os.path.join(validation_path, 'Preds'), os.path.join(validation_path, 'Masks')], test_path=[os.path.join(test_path, 'Preds'), os.path.join(test_path, 'Masks')], ROC_cruve_save_path=ROC_path)
  File "C:\Users\83549\Github Projects\Radiogenemics--on-Ivy-Gap-Branch\trainHelper.py", line 171, in evalation_all
    thresold = ROC_to_calculate_thresold(pred_path=train_path[0], truth_path=train_path[1], save_path=ROC_cruve_save_path, save_or_not=True)
  File "C:\Users\83549\Github Projects\Radiogenemics--on-Ivy-Gap-Branch\trainHelper.py", line 82, in ROC_to_calculate_thresold
    tmp_pred = tmp_pred[tmp_pred >= threshold] = 255
TypeError: 'int' object does not support item assignment

exception in epoch1
Traceback (most recent call last):
  File "C:\Users\83549\Github Projects\Radiogenemics--on-Ivy-Gap-Branch\train.py", line 183, in <module>
    evl_dict = trainHelper.evalation_all(train_path=[os.path.join(train_path, 'Preds'), os.path.join(train_path, 'Masks')], validation_path=[os.path.join(validation_path, 'Preds'), os.path.join(validation_path, 'Masks')], test_path=[os.path.join(test_path, 'Preds'), os.path.join(test_path, 'Masks')], ROC_cruve_save_path=ROC_path)
  File "C:\Users\83549\Github Projects\Radiogenemics--on-Ivy-Gap-Branch\trainHelper.py", line 171, in evalation_all
    thresold = ROC_to_calculate_thresold(pred_path=train_path[0], truth_path=train_path[1], save_path=ROC_cruve_save_path, save_or_not=True)
  File "C:\Users\83549\Github Projects\Radiogenemics--on-Ivy-Gap-Branch\trainHelper.py", line 94, in ROC_to_calculate_thresold
    FPR = np.append(FPR, FP / (FP + TN))
ZeroDivisionError: division by zero

exception in epoch1
Traceback (most recent call last):
  File "C:\Users\83549\Github Projects\Radiogenemics--on-Ivy-Gap-Branch\train.py", line 183, in <module>
    evl_dict = trainHelper.evalation_all(train_path=[os.path.join(train_path, 'Preds'), os.path.join(train_path, 'Masks')], validation_path=[os.path.join(validation_path, 'Preds'), os.path.join(validation_path, 'Masks')], test_path=[os.path.join(test_path, 'Preds'), os.path.join(test_path, 'Masks')], ROC_cruve_save_path=ROC_path)
  File "C:\Users\83549\Github Projects\Radiogenemics--on-Ivy-Gap-Branch\trainHelper.py", line 189, in evalation_all
    for i in len(range(train_preds)):
TypeError: 'list' object cannot be interpreted as an integer

exception in epoch1
Traceback (most recent call last):
  File "C:\Users\83549\Github Projects\Radiogenemics--on-Ivy-Gap-Branch\train.py", line 103, in <module>
    for i, (image, mask) in tqdm(enumerate(train_loader), desc=f"train_{epoch}", total=len(train_loader)):
  File "C:\Users\83549\anaconda3\envs\PyTorch-gpu\lib\site-packages\tqdm\std.py", line 1180, in __iter__
    for obj in iterable:
  File "C:\Users\83549\anaconda3\envs\PyTorch-gpu\lib\site-packages\torch\utils\data\dataloader.py", line 521, in __next__
    data = self._next_data()
  File "C:\Users\83549\anaconda3\envs\PyTorch-gpu\lib\site-packages\torch\utils\data\dataloader.py", line 561, in _next_data
    data = self._dataset_fetcher.fetch(index)  # may raise StopIteration
  File "C:\Users\83549\anaconda3\envs\PyTorch-gpu\lib\site-packages\torch\utils\data\_utils\fetch.py", line 44, in fetch
    data = [self.dataset[idx] for idx in possibly_batched_index]
  File "C:\Users\83549\anaconda3\envs\PyTorch-gpu\lib\site-packages\torch\utils\data\_utils\fetch.py", line 44, in <listcomp>
    data = [self.dataset[idx] for idx in possibly_batched_index]
  File "C:\Users\83549\anaconda3\envs\PyTorch-gpu\lib\site-packages\torch\utils\data\dataset.py", line 311, in __getitem__
    return self.dataset[self.indices[idx]]
  File "C:\Users\83549\Github Projects\Radiogenemics--on-Ivy-Gap-Branch\data.py", line 76, in __getitem__
    msk = gray2Binary(msk)
  File "C:\Users\83549\Github Projects\Radiogenemics--on-Ivy-Gap-Branch\utils.py", line 43, in gray2Binary
    if img[i, j] > 0:
KeyboardInterrupt

exception in epoch1
Traceback (most recent call last):
  File "C:\Users\83549\Github Projects\Radiogenemics--on-Ivy-Gap-Branch\train.py", line 103, in <module>
    for i, (image, mask) in tqdm(enumerate(train_loader), desc=f"train_{epoch}", total=len(train_loader)):
  File "C:\Users\83549\anaconda3\envs\PyTorch-gpu\lib\site-packages\tqdm\std.py", line 1180, in __iter__
    for obj in iterable:
  File "C:\Users\83549\anaconda3\envs\PyTorch-gpu\lib\site-packages\torch\utils\data\dataloader.py", line 521, in __next__
    data = self._next_data()
  File "C:\Users\83549\anaconda3\envs\PyTorch-gpu\lib\site-packages\torch\utils\data\dataloader.py", line 561, in _next_data
    data = self._dataset_fetcher.fetch(index)  # may raise StopIteration
  File "C:\Users\83549\anaconda3\envs\PyTorch-gpu\lib\site-packages\torch\utils\data\_utils\fetch.py", line 44, in fetch
    data = [self.dataset[idx] for idx in possibly_batched_index]
  File "C:\Users\83549\anaconda3\envs\PyTorch-gpu\lib\site-packages\torch\utils\data\_utils\fetch.py", line 44, in <listcomp>
    data = [self.dataset[idx] for idx in possibly_batched_index]
  File "C:\Users\83549\anaconda3\envs\PyTorch-gpu\lib\site-packages\torch\utils\data\dataset.py", line 311, in __getitem__
    return self.dataset[self.indices[idx]]
  File "C:\Users\83549\Github Projects\Radiogenemics--on-Ivy-Gap-Branch\data.py", line 76, in __getitem__
    msk = gray2Binary(msk)
  File "C:\Users\83549\Github Projects\Radiogenemics--on-Ivy-Gap-Branch\utils.py", line 43, in gray2Binary
    if img[i, j] > 0:
KeyboardInterrupt

exception in epoch1
Traceback (most recent call last):
  File "C:\Users\83549\Github Projects\Radiogenemics--on-Ivy-Gap-Branch\train.py", line 183, in <module>
    evl_dict = trainHelper.evalation_all(train_path=[os.path.join(train_path, 'Preds'), os.path.join(train_path, 'Masks')], validation_path=[os.path.join(validation_path, 'Preds'), os.path.join(validation_path, 'Masks')], test_path=[os.path.join(test_path, 'Preds'), os.path.join(test_path, 'Masks')], ROC_cruve_save_path=os.path.join(ROC_path, f'epoch{i}.png'))
  File "C:\Users\83549\Github Projects\Radiogenemics--on-Ivy-Gap-Branch\trainHelper.py", line 193, in evalation_all
    for i in len(train_preds):
TypeError: 'int' object is not iterable

exception in epoch1
Traceback (most recent call last):
  File "C:\Users\83549\Github Projects\Radiogenemics--on-Ivy-Gap-Branch\train.py", line 183, in <module>
    evl_dict = trainHelper.evalation_all(train_path=[os.path.join(train_path, 'Preds'), os.path.join(train_path, 'Masks')], validation_path=[os.path.join(validation_path, 'Preds'), os.path.join(validation_path, 'Masks')], test_path=[os.path.join(test_path, 'Preds'), os.path.join(test_path, 'Masks')], ROC_cruve_save_path=os.path.join(ROC_path, f'epoch{i}.png'))
  File "C:\Users\83549\Github Projects\Radiogenemics--on-Ivy-Gap-Branch\trainHelper.py", line 178, in evalation_all
    thresold = ROC_to_calculate_thresold(pred_path=train_path[0], truth_path=train_path[1], save_path=ROC_cruve_save_path, save_or_not=True)
  File "C:\Users\83549\Github Projects\Radiogenemics--on-Ivy-Gap-Branch\trainHelper.py", line 96, in ROC_to_calculate_thresold
    TN += len(np.where(tmp_pred + tmp_truth == 0)[0])
  File "<__array_function__ internals>", line 5, in where
KeyboardInterrupt

exception in epoch1
Traceback (most recent call last):
  File "C:\Users\83549\Github Projects\Radiogenemics--on-Ivy-Gap-Branch\train.py", line 117, in <module>
    train_preds = torch.cat((train_preds, predict_image), 0)
RuntimeError: Expected all tensors to be on the same device, but found at least two devices, cpu and cuda:0! (when checking arugment for argument tensors in method wrapper__cat)

exception in epoch1
Traceback (most recent call last):
  File "C:\Users\83549\Github Projects\Radiogenemics--on-Ivy-Gap-Branch\train.py", line 111, in <module>
    loss_list = np.append(loss_list, train_loss.item())
KeyboardInterrupt

exception in epoch1
Traceback (most recent call last):
  File "C:\Users\83549\Github Projects\Radiogenemics--on-Ivy-Gap-Branch\train.py", line 113, in <module>
    train_preds = torch.cat((train_preds, predict_image.cpu().detach()), 0)
KeyboardInterrupt

exception in epoch1
Traceback (most recent call last):
  File "C:\Users\83549\Github Projects\Radiogenemics--on-Ivy-Gap-Branch\train.py", line 138, in <module>
    predict_image = net(image)
  File "C:\Users\83549\anaconda3\envs\PyTorch-gpu\lib\site-packages\torch\nn\modules\module.py", line 1051, in _call_impl
    return forward_call(*input, **kwargs)
  File "C:\Users\83549\Github Projects\Radiogenemics--on-Ivy-Gap-Branch\unet.py", line 83, in forward
    R1 = self.c9(self.u4(R2, L1))
  File "C:\Users\83549\anaconda3\envs\PyTorch-gpu\lib\site-packages\torch\nn\modules\module.py", line 1051, in _call_impl
    return forward_call(*input, **kwargs)
  File "C:\Users\83549\Github Projects\Radiogenemics--on-Ivy-Gap-Branch\unet.py", line 23, in forward
    return self.layer(x)
  File "C:\Users\83549\anaconda3\envs\PyTorch-gpu\lib\site-packages\torch\nn\modules\module.py", line 1051, in _call_impl
    return forward_call(*input, **kwargs)
  File "C:\Users\83549\anaconda3\envs\PyTorch-gpu\lib\site-packages\torch\nn\modules\container.py", line 139, in forward
    input = module(input)
  File "C:\Users\83549\anaconda3\envs\PyTorch-gpu\lib\site-packages\torch\nn\modules\module.py", line 1051, in _call_impl
    return forward_call(*input, **kwargs)
  File "C:\Users\83549\anaconda3\envs\PyTorch-gpu\lib\site-packages\torch\nn\modules\conv.py", line 443, in forward
    return self._conv_forward(input, self.weight, self.bias)
  File "C:\Users\83549\anaconda3\envs\PyTorch-gpu\lib\site-packages\torch\nn\modules\conv.py", line 436, in _conv_forward
    return F.conv2d(F.pad(input, self._reversed_padding_repeated_twice, mode=self.padding_mode),
RuntimeError: CUDA out of memory. Tried to allocate 64.00 MiB (GPU 0; 6.00 GiB total capacity; 5.27 GiB already allocated; 0 bytes free; 5.31 GiB reserved in total by PyTorch)

exception in epoch1
Traceback (most recent call last):
  File "C:\Users\83549\Github Projects\Radiogenemics--on-Ivy-Gap-Branch\train.py", line 191, in <module>
    evl_dict = trainHelper.evalation_all(train_preds, train_truths, validation_preds, validation_truths, test_preds, test_truths)
TypeError: evalation_all() missing 1 required positional argument: 'threshold'

exception in epoch2
Traceback (most recent call last):
  File "C:\Users\83549\Github Projects\Radiogenemics--on-Ivy-Gap-Branch\train.py", line 113, in <module>
    train_preds = torch.cat((train_preds, predict_image.cpu().detach()), 0)
KeyboardInterrupt

exception in epoch1
Traceback (most recent call last):
  File "c:\Users\83549\Github Projects\Radiogenemics--on-Ivy-Gap\train.py", line 107, in <module>
    predict_image = net(image)
  File "C:\Users\83549\anaconda3\envs\PyTorch-gpu\lib\site-packages\torch\nn\modules\module.py", line 1051, in _call_impl
    return forward_call(*input, **kwargs)
  File "c:\Users\83549\Github Projects\Radiogenemics--on-Ivy-Gap\unet.py", line 71, in forward
    L1 = self.c1(x)
  File "C:\Users\83549\anaconda3\envs\PyTorch-gpu\lib\site-packages\torch\nn\modules\module.py", line 1051, in _call_impl
    return forward_call(*input, **kwargs)
  File "c:\Users\83549\Github Projects\Radiogenemics--on-Ivy-Gap\unet.py", line 20, in forward
    return self.layer(x)
  File "C:\Users\83549\anaconda3\envs\PyTorch-gpu\lib\site-packages\torch\nn\modules\module.py", line 1051, in _call_impl
    return forward_call(*input, **kwargs)
  File "C:\Users\83549\anaconda3\envs\PyTorch-gpu\lib\site-packages\torch\nn\modules\container.py", line 139, in forward
    input = module(input)
  File "C:\Users\83549\anaconda3\envs\PyTorch-gpu\lib\site-packages\torch\nn\modules\module.py", line 1051, in _call_impl
    return forward_call(*input, **kwargs)
  File "C:\Users\83549\anaconda3\envs\PyTorch-gpu\lib\site-packages\torch\nn\modules\conv.py", line 587, in forward
    return self._conv_forward(input, self.weight, self.bias)
  File "C:\Users\83549\anaconda3\envs\PyTorch-gpu\lib\site-packages\torch\nn\modules\conv.py", line 582, in _conv_forward
    return F.conv3d(
RuntimeError: Expected 5-dimensional input for 5-dimensional weight [64, 1, 3, 3, 3], but got 4-dimensional input of size [2, 256, 256, 128] instead

exception in epoch1
Traceback (most recent call last):
  File "c:\Users\83549\Github Projects\Radiogenemics--on-Ivy-Gap\train.py", line 107, in <module>
    predict_image = net(image)
  File "C:\Users\83549\anaconda3\envs\PyTorch-gpu\lib\site-packages\torch\nn\modules\module.py", line 1051, in _call_impl
    return forward_call(*input, **kwargs)
  File "c:\Users\83549\Github Projects\Radiogenemics--on-Ivy-Gap\unet.py", line 71, in forward
    L1 = self.c1(x)
  File "C:\Users\83549\anaconda3\envs\PyTorch-gpu\lib\site-packages\torch\nn\modules\module.py", line 1051, in _call_impl
    return forward_call(*input, **kwargs)
  File "c:\Users\83549\Github Projects\Radiogenemics--on-Ivy-Gap\unet.py", line 20, in forward
    return self.layer(x)
  File "C:\Users\83549\anaconda3\envs\PyTorch-gpu\lib\site-packages\torch\nn\modules\module.py", line 1051, in _call_impl
    return forward_call(*input, **kwargs)
  File "C:\Users\83549\anaconda3\envs\PyTorch-gpu\lib\site-packages\torch\nn\modules\container.py", line 139, in forward
    input = module(input)
  File "C:\Users\83549\anaconda3\envs\PyTorch-gpu\lib\site-packages\torch\nn\modules\module.py", line 1051, in _call_impl
    return forward_call(*input, **kwargs)
  File "C:\Users\83549\anaconda3\envs\PyTorch-gpu\lib\site-packages\torch\nn\modules\dropout.py", line 142, in forward
    return F.dropout3d(input, self.p, self.training, self.inplace)
  File "C:\Users\83549\anaconda3\envs\PyTorch-gpu\lib\site-packages\torch\nn\functional.py", line 1226, in dropout3d
    return _VF.feature_dropout_(input, p, training) if inplace else _VF.feature_dropout(input, p, training)
RuntimeError: CUDA out of memory. Tried to allocate 2.00 GiB (GPU 0; 6.00 GiB total capacity; 4.45 GiB already allocated; 0 bytes free; 4.72 GiB reserved in total by PyTorch)

exception in epoch1
Traceback (most recent call last):
  File "c:\Users\83549\Github Projects\Radiogenemics--on-Ivy-Gap\train.py", line 116, in <module>
    predict_image[i] = torch.FloatTensor(resize_3d_image(predict_image[i].clone().cpu().detach().numpy(), original_mask[i].shape, mode='nearest'))
  File "c:\Users\83549\Github Projects\Radiogenemics--on-Ivy-Gap\utils.py", line 54, in resize_3d_image
    resize_img = itpl.zoom(img, (resize[0] / img.shape[0], resize[1] / img.shape[1], resize[2] / img.shape[2]), mode=mode)
  File "C:\Users\83549\anaconda3\envs\PyTorch-gpu\lib\site-packages\scipy\ndimage\interpolation.py", line 767, in zoom
    zoom = _ni_support._normalize_sequence(zoom, input.ndim)
  File "C:\Users\83549\anaconda3\envs\PyTorch-gpu\lib\site-packages\scipy\ndimage\_ni_support.py", line 67, in _normalize_sequence
    raise RuntimeError(err)
RuntimeError: sequence argument must have length equal to input rank

exception in epoch1
Traceback (most recent call last):
  File "c:\Users\83549\Github Projects\Radiogenemics--on-Ivy-Gap\train.py", line 116, in <module>
    predict_image[i] = torch.FloatTensor(resize_3d_image(predict_image[i].clone().cpu().detach().numpy(), original_mask[i].shape, mode='nearest'))
  File "c:\Users\83549\Github Projects\Radiogenemics--on-Ivy-Gap\utils.py", line 54, in resize_3d_image
    resize_img = itpl.zoom(img, (resize[0] / img.shape[0], resize[1] / img.shape[1], resize[2] / img.shape[2]), mode=mode)
  File "C:\Users\83549\anaconda3\envs\PyTorch-gpu\lib\site-packages\scipy\ndimage\interpolation.py", line 767, in zoom
    zoom = _ni_support._normalize_sequence(zoom, input.ndim)
  File "C:\Users\83549\anaconda3\envs\PyTorch-gpu\lib\site-packages\scipy\ndimage\_ni_support.py", line 67, in _normalize_sequence
    raise RuntimeError(err)
RuntimeError: sequence argument must have length equal to input rank

exception in epoch1
Traceback (most recent call last):
  File "c:\Users\83549\Github Projects\Radiogenemics--on-Ivy-Gap\train.py", line 116, in <module>
    predict_image[i] = torch.FloatTensor(resize_3d_image(predict_image[i].clone().cpu().detach().numpy(), original_mask[i].shape, mode='nearest'))
  File "c:\Users\83549\Github Projects\Radiogenemics--on-Ivy-Gap\utils.py", line 54, in resize_3d_image
    resize_img = itpl.zoom(img, (resize[0] / img.shape[0], resize[1] / img.shape[1], resize[2] / img.shape[2]), mode=mode)
  File "C:\Users\83549\anaconda3\envs\PyTorch-gpu\lib\site-packages\scipy\ndimage\interpolation.py", line 767, in zoom
    zoom = _ni_support._normalize_sequence(zoom, input.ndim)
  File "C:\Users\83549\anaconda3\envs\PyTorch-gpu\lib\site-packages\scipy\ndimage\_ni_support.py", line 67, in _normalize_sequence
    raise RuntimeError(err)
RuntimeError: sequence argument must have length equal to input rank

exception in epoch1
Traceback (most recent call last):
  File "c:\Users\83549\Github Projects\Radiogenemics--on-Ivy-Gap\train.py", line 117, in <module>
    predict_image[i] = torch.FloatTensor(resize_3d_image(torch.squeeze(predict_image[i].clone()).cpu().detach().numpy(), original_mask[i].shape, mode='nearest'))
RuntimeError: The expanded size of the tensor (32) must match the existing size (229) at non-singleton dimension 3.  Target sizes: [1, 128, 128, 32].  Tensor sizes: [193, 229]

exception in epoch1
Traceback (most recent call last):
  File "c:\Users\83549\Github Projects\Radiogenemics--on-Ivy-Gap\train.py", line 117, in <module>
    predict_image[i] = torch.FloatTensor(resize_3d_image(torch.squeeze(predict_image[i].clone()).cpu().detach().numpy(), original_mask[i].shape, mode='nearest'))
RuntimeError: The expanded size of the tensor (32) must match the existing size (229) at non-singleton dimension 3.  Target sizes: [1, 128, 128, 32].  Tensor sizes: [193, 229]

exception in epoch1
Traceback (most recent call last):
  File "c:\Users\83549\Github Projects\Radiogenemics--on-Ivy-Gap\train.py", line 118, in <module>
    predict_image[i] = torch.FloatTensor(resize_3d_image(torch.squeeze(predict_image[i].clone()).cpu().detach().numpy(), original_mask[i].shape[2:], mode='nearest'))
  File "c:\Users\83549\Github Projects\Radiogenemics--on-Ivy-Gap\utils.py", line 54, in resize_3d_image
    resize_img = itpl.zoom(img, (resize[0] / img.shape[0], resize[1] / img.shape[1], resize[2] / img.shape[2]), mode=mode)
IndexError: tuple index out of range

exception in epoch1
Traceback (most recent call last):
  File "c:\Users\83549\Github Projects\Radiogenemics--on-Ivy-Gap\train.py", line 118, in <module>
    predict_image[i] = torch.FloatTensor(resize_3d_image(torch.squeeze(predict_image[i].clone()).cpu().detach().numpy(), original_mask[i].shape[2:], mode='nearest'))
  File "c:\Users\83549\Github Projects\Radiogenemics--on-Ivy-Gap\utils.py", line 54, in resize_3d_image
    resize_img = itpl.zoom(img, (resize[0] / img.shape[0], resize[1] / img.shape[1], resize[2] / img.shape[2]), mode=mode)
IndexError: tuple index out of range

exception in epoch1
Traceback (most recent call last):
  File "c:\Users\83549\Github Projects\Radiogenemics--on-Ivy-Gap\train.py", line 118, in <module>
    predict_image[i] = torch.FloatTensor(resize_3d_image(torch.squeeze(predict_image[i].clone()).cpu().detach().numpy(), original_mask[i].shape[1:], mode='nearest'))
RuntimeError: The expanded size of the tensor (32) must match the existing size (193) at non-singleton dimension 3.  Target sizes: [1, 128, 128, 32].  Tensor sizes: [193, 229, 193]

exception in epoch1
Traceback (most recent call last):
  File "c:\Users\83549\Github Projects\Radiogenemics--on-Ivy-Gap\train.py", line 118, in <module>
    predict_image[i] = torch.FloatTensor(resize_3d_image(torch.squeeze(predict_image[i].clone()).cpu().detach().numpy(), original_mask[i].shape[1:], mode='nearest')).unsqueeze(0)
RuntimeError: The expanded size of the tensor (32) must match the existing size (193) at non-singleton dimension 3.  Target sizes: [1, 128, 128, 32].  Tensor sizes: [193, 229, 193]

exception in epoch1
Traceback (most recent call last):
  File "c:\Users\83549\Github Projects\Radiogenemics--on-Ivy-Gap\train.py", line 119, in <module>
    predict_image[i] = torch.FloatTensor(resize_3d_image(torch.squeeze(predict_image[i].clone()).cpu().detach().numpy(), original_mask[i].shape[1:], mode='nearest')).unsqueeze(0)
RuntimeError: The expanded size of the tensor (32) must match the existing size (193) at non-singleton dimension 3.  Target sizes: [1, 128, 128, 32].  Tensor sizes: [193, 229, 193]

exception in epoch1
Traceback (most recent call last):
  File "c:\Users\83549\Github Projects\Radiogenemics--on-Ivy-Gap\train.py", line 120, in <module>
    resize_predict_image[i] = torch.FloatTensor(resize_3d_image(torch.squeeze(predict_image[i].clone()).cpu().detach().numpy(), original_mask[i].shape[1:], mode='nearest')).unsqueeze(0)
IndexError: index 0 is out of bounds for dimension 0 with size 0

exception in epoch1
Traceback (most recent call last):
  File "c:\Users\83549\Github Projects\Radiogenemics--on-Ivy-Gap\train.py", line 120, in <module>
    resize_predict_image[i] = torch.FloatTensor(resize_3d_image(torch.squeeze(predict_image[i].clone()).cpu().detach().numpy(), original_mask[i].shape[1:], mode='nearest')).unsqueeze(0)
IndexError: index 0 is out of bounds for dimension 0 with size 0

exception in epoch1
Traceback (most recent call last):
  File "c:\Users\83549\Github Projects\Radiogenemics--on-Ivy-Gap\train.py", line 120, in <module>
    resize_predict_image[i] = torch.FloatTensor(resize_3d_image(torch.squeeze(predict_image[i].clone()).cpu().detach().numpy(), original_mask[i].shape[1:], mode='nearest')).unsqueeze(0)
IndexError: index 0 is out of bounds for dimension 0 with size 0

exception in epoch1
Traceback (most recent call last):
  File "c:\Users\83549\Github Projects\Radiogenemics--on-Ivy-Gap\train.py", line 120, in <module>
    resize_predict_image = torch.cat((resize_predict_image ,torch.FloatTensor(resize_3d_image(torch.squeeze(predict_image[i].clone()).cpu().detach().numpy(), original_mask[i].shape[1:], mode='nearest')).unsqueeze(0)), 0)
  File "c:\Users\83549\Github Projects\Radiogenemics--on-Ivy-Gap\utils.py", line 54, in resize_3d_image
    resize_img = itpl.zoom(img, (resize[0] / img.shape[0], resize[1] / img.shape[1], resize[2] / img.shape[2]), mode=mode)
  File "C:\Users\83549\anaconda3\envs\PyTorch-gpu\lib\site-packages\scipy\ndimage\interpolation.py", line 785, in zoom
    filtered = spline_filter(padded, order, output=numpy.float64,
  File "C:\Users\83549\anaconda3\envs\PyTorch-gpu\lib\site-packages\scipy\ndimage\interpolation.py", line 189, in spline_filter
    spline_filter1d(input, order, axis, output=output, mode=mode)
  File "C:\Users\83549\anaconda3\envs\PyTorch-gpu\lib\site-packages\scipy\ndimage\interpolation.py", line 131, in spline_filter1d
    _nd_image.spline_filter1d(input, order, axis, output, mode)
KeyboardInterrupt

exception in epoch1
Traceback (most recent call last):
  File "c:\Users\83549\Github Projects\Radiogenemics--on-Ivy-Gap\train.py", line 107, in <module>
    predict_image = net(image)
  File "C:\Users\83549\anaconda3\envs\PyTorch-gpu\lib\site-packages\torch\nn\modules\module.py", line 1051, in _call_impl
    return forward_call(*input, **kwargs)
  File "c:\Users\83549\Github Projects\Radiogenemics--on-Ivy-Gap\unet.py", line 79, in forward
    R1 = self.c9(self.u4(R2, L1))
  File "C:\Users\83549\anaconda3\envs\PyTorch-gpu\lib\site-packages\torch\nn\modules\module.py", line 1051, in _call_impl
    return forward_call(*input, **kwargs)
  File "c:\Users\83549\Github Projects\Radiogenemics--on-Ivy-Gap\unet.py", line 20, in forward
    return self.layer(x)
  File "C:\Users\83549\anaconda3\envs\PyTorch-gpu\lib\site-packages\torch\nn\modules\module.py", line 1051, in _call_impl
    return forward_call(*input, **kwargs)
  File "C:\Users\83549\anaconda3\envs\PyTorch-gpu\lib\site-packages\torch\nn\modules\container.py", line 139, in forward
    input = module(input)
  File "C:\Users\83549\anaconda3\envs\PyTorch-gpu\lib\site-packages\torch\nn\modules\module.py", line 1051, in _call_impl
    return forward_call(*input, **kwargs)
  File "C:\Users\83549\anaconda3\envs\PyTorch-gpu\lib\site-packages\torch\nn\modules\conv.py", line 587, in forward
    return self._conv_forward(input, self.weight, self.bias)
  File "C:\Users\83549\anaconda3\envs\PyTorch-gpu\lib\site-packages\torch\nn\modules\conv.py", line 582, in _conv_forward
    return F.conv3d(
RuntimeError: CUDA out of memory. Tried to allocate 256.00 MiB (GPU 0; 6.00 GiB total capacity; 5.12 GiB already allocated; 0 bytes free; 5.22 GiB reserved in total by PyTorch)

exception in epoch1
Traceback (most recent call last):
  File "c:\Users\83549\Github Projects\Radiogenemics--on-Ivy-Gap\train.py", line 120, in <module>
    resize_predict_image = torch.cat((resize_predict_image ,torch.FloatTensor(resize_3d_image(torch.squeeze(predict_image[i].clone()).cpu().detach().numpy(), original_mask[i].shape[1:], mode='nearest')).unsqueeze(0)), 0)
  File "c:\Users\83549\Github Projects\Radiogenemics--on-Ivy-Gap\utils.py", line 54, in resize_3d_image
    resize_img = itpl.zoom(img, (resize[0] / img.shape[0], resize[1] / img.shape[1], resize[2] / img.shape[2]), mode=mode)
  File "C:\Users\83549\anaconda3\envs\PyTorch-gpu\lib\site-packages\scipy\ndimage\interpolation.py", line 817, in zoom
    _nd_image.zoom_shift(filtered, zoom, None, output, order, mode, cval, npad,
KeyboardInterrupt

exception in epoch1
Traceback (most recent call last):
  File "c:\Users\83549\Github Projects\Radiogenemics--on-Ivy-Gap\train.py", line 120, in <module>
    resize_predict_image = torch.cat((resize_predict_image ,torch.FloatTensor(resize_3d_image(torch.squeeze(predict_image[i].clone()).cpu().detach().numpy(), original_mask[i].shape[1:], mode='nearest')).unsqueeze(0).unsqueeze(0)), 0)
  File "c:\Users\83549\Github Projects\Radiogenemics--on-Ivy-Gap\utils.py", line 54, in resize_3d_image
    resize_img = itpl.zoom(img, (resize[0] / img.shape[0], resize[1] / img.shape[1], resize[2] / img.shape[2]), mode=mode)
  File "C:\Users\83549\anaconda3\envs\PyTorch-gpu\lib\site-packages\scipy\ndimage\interpolation.py", line 785, in zoom
    filtered = spline_filter(padded, order, output=numpy.float64,
  File "C:\Users\83549\anaconda3\envs\PyTorch-gpu\lib\site-packages\scipy\ndimage\interpolation.py", line 189, in spline_filter
    spline_filter1d(input, order, axis, output=output, mode=mode)
  File "C:\Users\83549\anaconda3\envs\PyTorch-gpu\lib\site-packages\scipy\ndimage\interpolation.py", line 131, in spline_filter1d
    _nd_image.spline_filter1d(input, order, axis, output, mode)
KeyboardInterrupt

exception in epoch1
Traceback (most recent call last):
  File "c:\Users\83549\Github Projects\Radiogenemics--on-Ivy-Gap\train.py", line 159, in <module>
    evl_dict = trainHelper.evalation_all(train_preds, train_truths, test_preds, test_truths, threshold)
  File "c:\Users\83549\Github Projects\Radiogenemics--on-Ivy-Gap\trainHelper.py", line 175, in evalation_all
    train_preds_copy[train_preds_copy < threshold] = 0
RuntimeError: [enforce fail at ..\c10\core\CPUAllocator.cpp:79] data. DefaultCPUAllocator: not enough memory: you tried to allocate 7791531240 bytes.

exception in epoch1
Traceback (most recent call last):
  File "c:\Users\83549\Github Projects\Radiogenemics--on-Ivy-Gap\train.py", line 159, in <module>
    evl_dict = trainHelper.evalation_all(train_preds, train_truths, test_preds, test_truths, threshold)
  File "c:\Users\83549\Github Projects\Radiogenemics--on-Ivy-Gap\trainHelper.py", line 175, in evalation_all
    train_preds_copy[train_preds_copy < threshold] = 0
RuntimeError: [enforce fail at ..\c10\core\CPUAllocator.cpp:79] data. DefaultCPUAllocator: not enough memory: you tried to allocate 7811663040 bytes.

exception in epoch1
Traceback (most recent call last):
  File "c:\Users\83549\Github Projects\Radiogenemics--on-Ivy-Gap\train.py", line 160, in <module>
    evl_dict = trainHelper.evalation_all(train_preds, train_truths, test_preds, test_truths, threshold)
  File "c:\Users\83549\Github Projects\Radiogenemics--on-Ivy-Gap\trainHelper.py", line 175, in evalation_all
    train_preds_copy[train_preds_copy < threshold] = 0
RuntimeError: [enforce fail at ..\c10\core\CPUAllocator.cpp:79] data. DefaultCPUAllocator: not enough memory: you tried to allocate 7845605480 bytes.

exception in epoch1
Traceback (most recent call last):
  File "c:\Users\83549\Github Projects\Radiogenemics--on-Ivy-Gap\train.py", line 159, in <module>
    evl_dict = trainHelper.evalation_all(train_preds, train_truths, test_preds, test_truths, threshold)
  File "c:\Users\83549\Github Projects\Radiogenemics--on-Ivy-Gap\trainHelper.py", line 175, in evalation_all
    train_preds_copy[train_preds_copy < threshold] = 0
RuntimeError: [enforce fail at ..\c10\core\CPUAllocator.cpp:79] data. DefaultCPUAllocator: not enough memory: you tried to allocate 7826643400 bytes.

exception in epoch1
Traceback (most recent call last):
  File "c:\Users\83549\Github Projects\Radiogenemics--on-Ivy-Gap\train.py", line 107, in <module>
    for i, (image, mask, original_mask) in tqdm(enumerate(train_loader), desc=f"train_{epoch}", total=len(train_loader)):
  File "C:\Users\83549\anaconda3\envs\PyTorch-gpu\lib\site-packages\tqdm\std.py", line 1180, in __iter__
    for obj in iterable:
  File "C:\Users\83549\anaconda3\envs\PyTorch-gpu\lib\site-packages\torch\utils\data\dataloader.py", line 521, in __next__
    data = self._next_data()
  File "C:\Users\83549\anaconda3\envs\PyTorch-gpu\lib\site-packages\torch\utils\data\dataloader.py", line 561, in _next_data
    data = self._dataset_fetcher.fetch(index)  # may raise StopIteration
  File "C:\Users\83549\anaconda3\envs\PyTorch-gpu\lib\site-packages\torch\utils\data\_utils\fetch.py", line 44, in fetch
    data = [self.dataset[idx] for idx in possibly_batched_index]
  File "C:\Users\83549\anaconda3\envs\PyTorch-gpu\lib\site-packages\torch\utils\data\_utils\fetch.py", line 44, in <listcomp>
    data = [self.dataset[idx] for idx in possibly_batched_index]
  File "c:\Users\83549\Github Projects\Radiogenemics--on-Ivy-Gap\data.py", line 57, in __getitem__
    msk = resize_3d_image(msk, self.resize, mode='nearest')
  File "c:\Users\83549\Github Projects\Radiogenemics--on-Ivy-Gap\utils.py", line 54, in resize_3d_image
    resize_img = itpl.zoom(img, (resize[0] / img.shape[0], resize[1] / img.shape[1], resize[2] / img.shape[2]), mode=mode)
  File "C:\Users\83549\anaconda3\envs\PyTorch-gpu\lib\site-packages\scipy\ndimage\interpolation.py", line 785, in zoom
    filtered = spline_filter(padded, order, output=numpy.float64,
  File "C:\Users\83549\anaconda3\envs\PyTorch-gpu\lib\site-packages\scipy\ndimage\interpolation.py", line 189, in spline_filter
    spline_filter1d(input, order, axis, output=output, mode=mode)
  File "C:\Users\83549\anaconda3\envs\PyTorch-gpu\lib\site-packages\scipy\ndimage\interpolation.py", line 131, in spline_filter1d
    _nd_image.spline_filter1d(input, order, axis, output, mode)
KeyboardInterrupt

exception in epoch1
Traceback (most recent call last):
  File "c:\Users\83549\Github Projects\Radiogenemics--on-Ivy-Gap\train.py", line 158, in <module>
    evl_dict = trainHelper.evalation_all(train_preds, train_truths, test_preds, test_truths, threshold)
  File "c:\Users\83549\Github Projects\Radiogenemics--on-Ivy-Gap\trainHelper.py", line 175, in evalation_all
    train_preds_copy[train_preds_copy < threshold] = 0
RuntimeError: [enforce fail at ..\c10\core\CPUAllocator.cpp:79] data. DefaultCPUAllocator: not enough memory: you tried to allocate 7780086800 bytes.

